<?xml version="1.0" ?>
<!-- =================================================================================== -->
<!-- |    This document was autogenerated by xacro from /home/kjwtu/ws_moveit/src/garbagebot_ros2/garbagebot_description/urdf/robots/garbagebot_arm.urdf.xacro | -->
<!-- |    EDITING THIS FILE BY HAND IS NOT RECOMMENDED                                 | -->
<!-- =================================================================================== -->
<robot name="garbagebot_arm">
  <link name="world"/>
  <joint name="virtual_joint" type="fixed">
    <parent link="world"/>
    <child link="base_link"/>
    <origin rpy="0 0 0" xyz="0 0 0"/>
  </joint>
  <link name="base_link">
    <inertial>
      <origin rpy="0 0 0" xyz="0 0 0.0"/>
      <mass value="0.33"/>
      <inertia ixx="0.000784" ixy="0.0" ixz="0.0" iyy="0.000867" iyz="0.0" izz="0.001598"/>
    </inertial>
    <visual>
      <geometry>
        <box size="3.0 0.05 1.0"/>
      </geometry>
      <origin rpy="0 0 0" xyz="0.0 0.0 0.0"/>
    </visual>
    <collision>
      <geometry>
        <box size="3.0 0.05 1.0"/>
      </geometry>
      <origin rpy="0 0 0" xyz="0.0 0.0 0.0"/>
    </collision>
  </link>
  <gazebo reference="base_link">
    <visual>
      <material>
        <ambient>0.5 0.5 0.5 1</ambient>
        <diffuse>0.5 0.5 0.5 1</diffuse>
        <specular>0.5 0.5 0.5 1</specular>
      </material>
    </visual>
  </gazebo>
  <link name="link1">
    <inertial>
      <origin rpy="0 0 0" xyz="0 0 0.0"/>
      <mass value="0.12"/>
      <inertia ixx="0.000148" ixy="0.0" ixz="0.0" iyy="0.000148" iyz="0.0" izz="9.6e-05"/>
    </inertial>
    <visual>
      <geometry>
        <box size="3.0 0.05 1.0"/>
      </geometry>
      <origin rpy="0 0 0" xyz="0.0 0.0 0.0"/>
    </visual>
    <collision>
      <geometry>
        <box size="3.0 0.05 1.0"/>
      </geometry>
      <origin rpy="0 0 0" xyz="0.0 0.0 0.0"/>
    </collision>
  </link>
  <link name="link2">
    <inertial>
      <origin rpy="0 0 0" xyz="0 0 0.0"/>
      <mass value="0.19"/>
      <inertia ixx="0.000148" ixy="0.0" ixz="0.0" iyy="0.000148" iyz="0.0" izz="9.6e-05"/>
    </inertial>
    <visual>
      <geometry>
        <box size="0.4 0.05 0.2"/>
      </geometry>
      <origin rpy="0 0 0" xyz="0.0 0.05 0.0"/>
    </visual>
    <collision>
      <geometry>
        <box size="0.4 0.05 0.2"/>
      </geometry>
      <origin rpy="0 0 0" xyz="0.0 0.05 0.0"/>
    </collision>
  </link>
  <link name="link3">
    <inertial>
      <origin rpy="0 0 0" xyz="0 0 0.0"/>
      <mass value="0.16"/>
      <inertia ixx="0.000148" ixy="0.0" ixz="0.0" iyy="0.000148" iyz="0.0" izz="9.6e-05"/>
    </inertial>
    <visual>
      <geometry>
        <cylinder length="1.0" radius="0.08"/>
      </geometry>
      <origin rpy="-1.5707963267948966 0 0" xyz="0 0.5 0"/>
    </visual>
    <collision>
      <geometry>
        <cylinder length="1.0" radius="0.08"/>
      </geometry>
      <origin rpy="-1.5707963267948966 0 0" xyz="0 0.5 0"/>
    </collision>
  </link>
  <link name="link4">
    <inertial>
      <origin rpy="0 0 0" xyz="0 0 0.0"/>
      <mass value="0.124"/>
      <inertia ixx="0.000103" ixy="0.0" ixz="0.0" iyy="0.000103" iyz="0.0" izz="9.6e-05"/>
    </inertial>
    <visual>
      <geometry>
        <cylinder length="1.0" radius="0.05"/>
      </geometry>
      <origin rpy="-1.5707963267948966 -1.5707963267948966 0" xyz="0 0.5 0"/>
    </visual>
    <collision>
      <geometry>
        <cylinder length="1.0" radius="0.05"/>
      </geometry>
      <origin rpy="-1.5707963267948966 -1.5707963267948966 0" xyz="0 0.5 0"/>
    </collision>
  </link>
  <link name="link6_flange">
    <inertial>
      <origin rpy="0 0 0" xyz="0 0 0.0"/>
      <mass value="0.035"/>
      <inertia ixx="1.49e-05" ixy="0.0" ixz="0.0" iyy="1.49e-05" iyz="0.0" izz="1.96e-05"/>
    </inertial>
    <visual>
      <geometry>
        <cylinder length="1.0" radius="0.05"/>
      </geometry>
      <origin rpy="0 -1.5707963267948966 0" xyz="0.0 0.0 0.0"/>
    </visual>
    <collision>
      <geometry>
        <cylinder length="1.0" radius="0.05"/>
      </geometry>
      <origin rpy="0 -1.5707963267948966 0" xyz="0.0 0.0 0.0"/>
    </collision>
  </link>
  <joint name="base_link_to_link1" type="fixed">
    <parent link="base_link"/>
    <child link="link1"/>
    <origin rpy="0 0 0" xyz="0 0 0"/>
  </joint>
  <joint name="link1_to_link2" type="prismatic">
    <axis xyz="1 0 0"/>
    <limit effort="56.0" lower="-1.0" upper="1.0" velocity="2.792527"/>
    <parent link="link1"/>
    <child link="link2"/>
    <origin rpy="0 0 0" xyz="0 0 0"/>
    <dynamics damping="0.0" friction="0.0"/>
  </joint>
  <joint name="link2_to_link3" type="revolute">
    <axis xyz="-1 0 0"/>
    <limit effort="56.0" lower="0" upper="2.0" velocity="2.792527"/>
    <parent link="link2"/>
    <child link="link3"/>
    <origin rpy="1.5707963267948966 0 0" xyz="0 0.05 0"/>
    <dynamics damping="0.0" friction="0.0"/>
  </joint>
  <joint name="link3_to_link4" type="prismatic">
    <axis xyz="0 1 0"/>
    <limit effort="56.0" lower="0" upper="0.8" velocity="2.792527"/>
    <parent link="link3"/>
    <child link="link4"/>
    <origin rpy="0 0 0" xyz="0 0.1 0"/>
    <dynamics damping="0.0" friction="0.0"/>
  </joint>
  <joint name="link4_to_link6_flange" type="revolute">
    <axis xyz="-1 0 0"/>
    <limit effort="56.0" lower="0" upper="2.0" velocity="2.792527"/>
    <parent link="link4"/>
    <child link="link6_flange"/>
    <origin rpy="0 0 0" xyz="0 1.0 0"/>
    <dynamics damping="0.0" friction="0.0"/>
  </joint>
  <gazebo reference="link1">
    <visual>
      <material>
        <ambient>0.5 0.5 0.5 1</ambient>
        <diffuse>0.5 0.5 0.5 1</diffuse>
        <specular>0.5 0.5 0.5 1</specular>
      </material>
    </visual>
  </gazebo>
  <gazebo reference="link2">
    <visual>
      <material>
        <ambient>1 1 1 1</ambient>
        <diffuse>1 1 1 1</diffuse>
        <specular>1 1 1 1</specular>
      </material>
    </visual>
  </gazebo>
  <gazebo reference="link3">
    <visual>
      <material>
        <ambient>1 1 1 1</ambient>
        <diffuse>1 1 1 1</diffuse>
        <specular>1 1 1 1</specular>
      </material>
    </visual>
  </gazebo>
  <gazebo reference="link4">
    <visual>
      <material>
        <ambient>1 1 1 1</ambient>
        <diffuse>1 1 1 1</diffuse>
        <specular>1 1 1 1</specular>
      </material>
    </visual>
  </gazebo>
  <gazebo reference="link6_flange">
    <visual>
      <material>
        <ambient>0.5 0.5 0.5 1</ambient>
        <diffuse>0.5 0.5 0.5 1</diffuse>
        <specular>0.5 0.5 0.5 1</specular>
      </material>
    </visual>
  </gazebo>
  <link name="gripper_base">
    <inertial>
      <origin rpy="0 0 0" xyz="0 0 0.0"/>
      <mass value="0.07"/>
      <inertia ixx="0.000010725" ixy="0.0" ixz="0.0" iyy="0.000014392" iyz="0.0" izz="0.000018517"/>
    </inertial>
    <visual>
      <geometry>
        <box size="1.0 0.05 0.05"/>
      </geometry>
      <origin rpy="0 0 0" xyz="0.0 0.0 0.0"/>
    </visual>
    <collision>
      <geometry>
        <box size="1.0 0.05 0.05"/>
      </geometry>
      <origin rpy="0 0 0" xyz="0.0 0.0 0.0"/>
    </collision>
  </link>
  <joint name="link6_flange_to_gripper_base" type="fixed">
    <parent link="link6_flange"/>
    <child link="gripper_base"/>
    <origin rpy="1.579 0 0" xyz="0 0 0.034"/>
  </joint>
  <link name="gripper_left">
    <inertial>
      <origin rpy="0 0 0" xyz="0 0 0.0"/>
      <mass value="0.007"/>
      <inertia ixx="1e-06" ixy="0.0" ixz="0.0" iyy="1e-06" iyz="0.0" izz="1e-06"/>
    </inertial>
    <visual>
      <geometry>
        <box size="0.05 1.0 0.05"/>
      </geometry>
      <origin rpy="0 0 0" xyz="-0.5 0.5 0.0"/>
    </visual>
    <collision>
      <geometry>
        <box size="0.05 1.0 0.05"/>
      </geometry>
      <origin rpy="0 0 0" xyz="-0.5 0.5 0.0"/>
    </collision>
  </link>
  <link name="gripper_right">
    <inertial>
      <origin rpy="0 0 0" xyz="0 0 0.0"/>
      <mass value="0.007"/>
      <inertia ixx="1e-06" ixy="0.0" ixz="0.0" iyy="1e-06" iyz="0.0" izz="1e-06"/>
    </inertial>
    <visual>
      <geometry>
        <box size="0.05 1.0 0.05"/>
      </geometry>
      <origin rpy="0 0 0" xyz="0.5 0.5 0.0"/>
    </visual>
    <collision>
      <geometry>
        <box size="0.05 1.0 0.05"/>
      </geometry>
      <origin rpy="0 0 0" xyz="0.5 0.5 0.0"/>
    </collision>
  </link>
  <joint name="gripper_base_to_gripper_left" type="prismatic">
    <axis xyz="1 0 0"/>
    <limit effort="56.0" lower="0.0" upper="0.5" velocity="2.792527"/>
    <parent link="gripper_base"/>
    <child link="gripper_left"/>
    <origin rpy="0 0 0" xyz="0 0 0"/>
    <dynamics damping="0.0" friction="0.0"/>
  </joint>
  <joint name="gripper_base_to_gripper_right" type="prismatic">
    <axis xyz="1 0 0"/>
    <limit effort="56.0" lower="0.0" upper="0.5" velocity="2.792527"/>
    <parent link="gripper_base"/>
    <child link="gripper_right"/>
    <origin rpy="0 0 0" xyz="0 0 0"/>
    <mimic joint="gripper_base_to_gripper_left" multiplier="-1.0" offset="0"/>
    <dynamics damping="0.0" friction="0.0"/>
  </joint>
  <gazebo reference="gripper_base">
    <visual>
      <material>
        <ambient>1 1 1 1</ambient>
        <diffuse>1 1 1 1</diffuse>
        <specular>1 1 1 1</specular>
      </material>
    </visual>
  </gazebo>
  <ros2_control name="RobotSystem" type="system">
    <hardware>
    </hardware>
    <joint name="link1_to_link2">
      <command_interface name="position">
        <param name="min">-2.879793</param>
        <param name="max">2.879793</param>
      </command_interface>
      <state_interface name="position"/>
    </joint>
    <joint name="link2_to_link3">
      <command_interface name="position">
        <param name="min">-2.879793</param>
        <param name="max">2.879793</param>
      </command_interface>
      <state_interface name="position"/>
    </joint>
    <joint name="link3_to_link4">
      <command_interface name="position">
        <param name="min">-2.879793</param>
        <param name="max">2.879793</param>
      </command_interface>
      <state_interface name="position"/>
    </joint>
    <joint name="link4_to_link5">
      <command_interface name="position">
        <param name="min">-2.879793</param>
        <param name="max">2.879793</param>
      </command_interface>
      <state_interface name="position"/>
    </joint>
    <joint name="link5_to_link6">
      <command_interface name="position">
        <param name="min">-2.879793</param>
        <param name="max">2.879793</param>
      </command_interface>
      <state_interface name="position"/>
    </joint>
    <joint name="link6_to_link6_flange">
      <command_interface name="position">
        <param name="min">-3.05</param>
        <param name="max">3.05</param>
      </command_interface>
      <state_interface name="position"/>
    </joint>
    <joint name="gripper_controller">
      <command_interface name="position">
        <param name="min">-0.7</param>
        <param name="max">0.15</param>
      </command_interface>
      <state_interface name="position"/>
      <state_interface name="velocity"/>
    </joint>
    <joint name="gripper_base_to_gripper_left2">
      <param name="mimic">gripper_controller</param>
      <param name="multiplier">1.0</param>
      <state_interface name="position"/>
      <state_interface name="velocity"/>
    </joint>
    <joint name="gripper_left3_to_gripper_left1">
      <param name="mimic">gripper_controller</param>
      <param name="multiplier">-1.0</param>
      <state_interface name="position"/>
      <state_interface name="velocity"/>
    </joint>
    <joint name="gripper_base_to_gripper_right3">
      <param name="mimic">gripper_controller</param>
      <param name="multiplier">-1.0</param>
      <state_interface name="position"/>
      <state_interface name="velocity"/>
    </joint>
    <joint name="gripper_base_to_gripper_right2">
      <param name="mimic">gripper_controller</param>
      <state_interface name="position"/>
      <state_interface name="velocity"/>
    </joint>
    <joint name="gripper_right3_to_gripper_right1">
      <param name="mimic">gripper_controller</param>
      <param name="multiplier">1.0</param>
      <state_interface name="position"/>
      <state_interface name="velocity"/>
    </joint>
  </ros2_control>
</robot>
