<?xml version="1.0" ?>
<sdf version="1.10">
  <model name="garbage_truck">
    <static>false</static>

    <!-- Chassis -->
    <link name="chassis">
      <pose>0 0 0.8 0 0 0</pose>
      <inertial>
        <mass>15000</mass>
        <inertia>
          <ixx>500</ixx> <iyy>1200</iyy> <izz>1000</izz>
          <ixy>0</ixy> <ixz>0</ixz> <iyz>0</iyz>
        </inertia>
      </inertial>
      <collision name="chassis_collision">
        <geometry>
          <box>
            <size>5 2 0.6</size>
          </box>
        </geometry>
      </collision>
      <visual name="chassis_visual">
        <geometry>
          <box>
            <size>5 2 0.5</size>
          </box>
        </geometry>
        <material>
          <script>
            <uri>file://media/materials/scripts/gazebo.material</uri>
            <name>Gazebo/Green</name>
          </script>
        </material>
      </visual>
    </link>

    <!-- Wheels -->
    <link name="wheel_front_left">
      <pose> 1.9 1.1 0.5 -1.5707 0 0</pose>
      <inertial>
        <mass>1000</mass>
      </inertial>
      <collision name="collision">
        <geometry>
          <cylinder>
            <radius>0.5</radius>
            <length>0.25</length>
          </cylinder>
        </geometry>
      </collision>
      <visual name="visual">
        <geometry>
          <cylinder>
            <radius>0.5</radius>
            <length>0.25</length>
          </cylinder>
        </geometry>
      </visual>
    </link>

    <joint name="joint_wheel_front_left" type="revolute">
      <parent>chassis</parent>
      <child>wheel_front_left</child>
      <axis>
        <xyz>0 1 0</xyz>
        <limit>
          <lower>-1.57</lower>
          <upper>1.57</upper>
        </limit>
      </axis>
    </joint>

    <link name="wheel_center_left">
      <pose> -0.9 1.1 0.5 -1.5707 0 0</pose>
      <inertial>
        <mass>1000</mass>
      </inertial>
      <collision name="collision">
        <geometry>
          <cylinder>
            <radius>0.5</radius>
            <length>0.25</length>
          </cylinder>
        </geometry>
      </collision>
      <visual name="visual">
        <geometry>
          <cylinder>
            <radius>0.5</radius>
            <length>0.25</length>
          </cylinder>
        </geometry>
      </visual>
    </link>

    <joint name="joint_wheel_center_left" type="revolute">
      <parent>chassis</parent>
      <child>wheel_center_left</child>
      <axis>
        <xyz>0 1 0</xyz>
        <limit>
          <lower>-1.57</lower>
          <upper>1.57</upper>
        </limit>
      </axis>
    </joint>

    <link name="wheel_back_left">
      <pose> -2 1.1 0.5 -1.5707 0 0</pose>
      <inertial>
        <mass>1000</mass>
      </inertial>
      <collision name="collision">
        <geometry>
          <cylinder>
            <radius>0.5</radius>
            <length>0.25</length>
          </cylinder>
        </geometry>
      </collision>
      <visual name="visual">
        <geometry>
          <cylinder>
            <radius>0.5</radius>
            <length>0.25</length>
          </cylinder>
        </geometry>
      </visual>
    </link>

    <joint name="joint_wheel_back_left" type="revolute">
      <parent>chassis</parent>
      <child>wheel_back_left</child>
      <axis>
        <xyz>0 1 0</xyz>
        <limit>
          <lower>-1.57</lower>
          <upper>1.57</upper>
        </limit>
      </axis>
    </joint>

    <link name="wheel_front_right">
      <pose> 1.9 -1.1 0.5 -1.5707 0 0</pose>
      <inertial>
        <mass>1000</mass>
      </inertial>
      <collision name="collision">
        <geometry>
          <cylinder>
            <radius>0.5</radius>
            <length>0.25</length>
          </cylinder>
        </geometry>
      </collision>
      <visual name="visual">
        <geometry>
          <cylinder>
            <radius>0.5</radius>
            <length>0.25</length>
          </cylinder>
        </geometry>
      </visual>
    </link>

    <joint name="joint_wheel_front_right" type="revolute">
      <parent>chassis</parent>
      <child>wheel_front_right</child>
      <axis>
        <xyz>0 1 0</xyz>
        <limit>
          <lower>-1.57</lower>
          <upper>1.57</upper>
        </limit>
      </axis>
    </joint>

    <link name="wheel_center_right">
      <pose> -0.9 -1.1 0.5 -1.5707 0 0</pose>
      <inertial>
        <mass>1000</mass>
      </inertial>
      <collision name="collision">
        <geometry>
          <cylinder>
            <radius>0.5</radius>
            <length>0.25</length>
          </cylinder>
        </geometry>
      </collision>
      <visual name="visual">
        <geometry>
          <cylinder>
            <radius>0.5</radius>
            <length>0.25</length>
          </cylinder>
        </geometry>
      </visual>
    </link>

    <joint name="joint_center_back_right" type="revolute">
      <parent>chassis</parent>
      <child>wheel_center_right</child>
      <axis>
        <xyz>0 1 0</xyz>
        <limit>
          <lower>-1.57</lower>
          <upper>1.57</upper>
        </limit>
      </axis>
    </joint>

    <link name="wheel_back_right">
      <pose> -2 -1.1 0.5 -1.5707 0 0</pose>
      <inertial>
        <mass>1000</mass>
      </inertial>
      <collision name="collision">
        <geometry>
          <cylinder>
            <radius>0.5</radius>
            <length>0.25</length>
          </cylinder>
        </geometry>
      </collision>
      <visual name="visual">
        <geometry>
          <cylinder>
            <radius>0.5</radius>
            <length>0.25</length>
          </cylinder>
        </geometry>
      </visual>
    </link>

    <joint name="joint_wheel_back_right" type="revolute">
      <parent>chassis</parent>
      <child>wheel_back_right</child>
      <axis>
        <xyz>0 1 0</xyz>
        <limit>
          <lower>-1.57</lower>
          <upper>1.57</upper>
        </limit>
      </axis>
    </joint>

    <link name="front">
      <pose>2.875 0 1.5 0 0 0</pose>
      <inertial>
        <mass>1000</mass>
        <inertia>
          <ixx>500</ixx> <iyy>1200</iyy> <izz>1000</izz>
          <ixy>0</ixy> <ixz>0</ixz> <iyz>0</iyz>
        </inertia>
      </inertial>
      <collision name="front_collision">
        <geometry>
          <box>
            <size> 0.75 2.5 2</size>
          </box>
        </geometry>
      </collision>
      <visual name="front_visual">
        <geometry>
          <box>
            <size> 0.75 2.5 2</size>
          </box>
        </geometry>
        <material>
          <script>
            <uri>file://media/materials/scripts/gazebo.material</uri>
            <name>Gazebo/Blue</name>
          </script>
        </material>
      </visual>
    </link>

    <joint name="joint_front_and_chasis" type="fixed">
      <parent>chassis</parent>
      <child>front</child>
    </joint>

    <link name="bottom">
      <pose> 0 0 1.05 0 0 0</pose>
      <inertial>
        <mass>1000</mass>
        <inertia>
          <ixx>500</ixx> <iyy>1200</iyy> <izz>1000</izz>
          <ixy>0</ixy> <ixz>0</ixz> <iyz>0</iyz>
        </inertia>
      </inertial>
      <collision name="bottom_collision">
        <geometry>
          <box>
            <size> 5 2.5 0.1</size>
          </box>
        </geometry>
      </collision>
      <visual name="bottom_visual">
        <geometry>
          <box>
            <size> 5 2.5 0.1</size>
          </box>
        </geometry>
        <material>
          <script>
            <uri>file://media/materials/scripts/gazebo.material</uri>
            <name>Gazebo/Green</name>
          </script>
        </material>
      </visual>
    </link>

    <joint name="joint_bottom_and_chasis" type="fixed">
      <parent>chassis</parent>
      <child>bottom</child>
    </joint>

    <link name="back">
      <pose> -2.375 0 1.75 0 0 0</pose>
      <inertial>
        <mass>1000</mass>
        <inertia>
          <ixx>500</ixx> <iyy>1200</iyy> <izz>1000</izz>
          <ixy>0</ixy> <ixz>0</ixz> <iyz>0</iyz>
        </inertia>
      </inertial>
      <collision name="back_collision">
        <geometry>
          <box>
            <size> 0.25 2.5 1.3</size>
          </box>
        </geometry>
      </collision>
      <visual name="back_visual">
        <geometry>
          <box>
            <size> 0.25 2.5 1.3</size>
          </box>
        </geometry>
        <material>
          <script>
            <uri>file://media/materials/scripts/gazebo.material</uri>
            <name>Gazebo/White</name>
          </script>
        </material>
      </visual>
    </link>

    <joint name="joint_back_and_bottom" type="fixed">
      <parent>bottom</parent>
      <child>back</child>
    </joint>

    <link name="left">
      <pose> 0 1.125 1.75 0 0 0</pose>
      <inertial>
        <mass>1000</mass>
        <inertia>
          <ixx>500</ixx> <iyy>1200</iyy> <izz>1000</izz>
          <ixy>0</ixy> <ixz>0</ixz> <iyz>0</iyz>
        </inertia>
      </inertial>
      <collision name="left_collision">
        <geometry>
          <box>
            <size> 5 0.25 1.3</size>
          </box>
        </geometry>
      </collision>
      <visual name="left_visual">
        <geometry>
          <box>
            <size> 5 0.25 1.3</size>
          </box>
        </geometry>
        <material>
          <script>
            <uri>file://media/materials/scripts/gazebo.material</uri>
            <name>Gazebo/White</name>
          </script>
        </material>
      </visual>
    </link>

    <joint name="joint_left_and_bottom" type="fixed">
      <parent>bottom</parent>
      <child>left</child>
    </joint>

    <link name="right">
      <pose> 0 -1.125 1.75 0 0 0</pose>
      <inertial>
        <mass>1000</mass>
        <inertia>
          <ixx>500</ixx> <iyy>1200</iyy> <izz>1000</izz>
          <ixy>0</ixy> <ixz>0</ixz> <iyz>0</iyz>
        </inertia>
      </inertial>
      <collision name="right_collision">
        <geometry>
          <box>
            <size> 5 0.25 1.3</size>
          </box>
        </geometry>
      </collision>
      <visual name="right_visual">
        <geometry>
          <box>
            <size> 5 0.25 1.3</size>
          </box>
        </geometry>
        <material>
          <script>
            <uri>file://media/materials/scripts/gazebo.material</uri>
            <name>Gazebo/White</name>
          </script>
        </material>
      </visual>
    </link>

    <joint name="joint_right_and_bottom" type="fixed">
      <parent>bottom</parent>
      <child>right</child>
    </joint>

    <!-- Define a link for the front camera -->
    <link name="front_camera_link">
      <pose>-3 0 1.5 0 0 0</pose>  <!-- Adjust position (x y z roll pitch yaw) -->

      <sensor name="front_camera" type="camera">
        <always_on>true</always_on>
        <update_rate>30</update_rate>  <!-- 30 FPS -->
        <camera>
          <horizontal_fov>1.57</horizontal_fov>  <!-- Field of View (90 degrees) -->
          <image>
            <width>640</width>
            <height>480</height>
            <format>R8G8B8</format>
          </image>
          <clip>
            <near>0.1</near>
            <far>100</far>
          </clip>
        </camera>
        <plugin name="camera_plugin" filename="libgazebo_ros_camera.so">
          <ros>
            <namespace>/garbage_truck</namespace>
            <remapping>image_raw:=camera/image_raw</remapping>
          </ros>
        </plugin>
      </sensor>
    </link>

  </model>
</sdf>
